Workbook

Sheet CW - ALL
A1: K64F with MULT2-B, all algorithms CW Build
B2: 9-axis | C2: Accel/Gyro | D2: Accel/Mag | E2: Gyro Only | F2: 2D Mag | G2: Accel (Tilt) | K2: Table 14 for CodeWarrior (Fusion K SysTicks)
A3: Fusion K Systicks | B3: 50.5 | C3: 10.6 | D3: 3.6 | E3: 4.5 | F3: 2.86 | G3: 3.1 | H3: =SUM(B3:G3) -> 75.16 | L3: =G2 -> Accel (Tilt) | M3: =F2 -> 2D Mag | N3: =E2 -> Gyro Only | O3: =D2 -> Accel/Mag | P3: =C2 -> Accel/Gyro | Q3: =B2 -> 9-axis
A4: Total K Systicks | B4: 4794 | C4: 4794 | D4: 4794 | E4: 4794 | F4: 4793 | G4: 4794 | H4: =AVERAGE(B4:G4) -> 4793.8333 | I4: =H4*25*1000 -> 1.1984583e+08 | K4: KL25Z | L4: =G35 -> 58 | M4: =F35 -> 46 | N4: =E35 -> 172 | O4: =D35 -> 72 | P4: =C35 -> 208 | Q4: =B35 -> 740
A5: % Fusion | B5: =B3/B4 -> 0.010534001 | C5: =C3/C4 -> 0.0022110972 | D5: =D3/D4 -> 0.00075093867 | E5: =E3/E4 -> 0.00093867334 | F5: =F3/F4 -> 0.00059670353 | G5: =G3/G4 -> 0.00064664164 | K5: KL26Z | L5: =G27 -> 58 | M5: =F27 -> 45 | N5: =E27 -> 171 | O5: =D27 -> 71 | P5: =C27 -> 210 | Q5: =B27 -> 740
A6: Total IDD (mA) | B6: 38 | C6: 38 | D6: 37.9 | E6: 37.9 | F6: 38.6 | G6: 38.5 | K6: KL46Z | L6: =G19 -> 59 | M6: =F19 -> 45 | N6: =E19 -> 171 | O6: =D19 -> 72 | P6: =C19 -> 207 | Q6: =B19 -> 740
A7: Fusion IDD (mA) | B7: =B5*B6 -> 0.40029203 | C7: =C5*C6 -> 0.084021694 | D7: =D5*D6 -> 0.028460576 | E7: =E5*E6 -> 0.03557572 | F7: =F5*F6 -> 0.023032756 | G7: =G5*G6 -> 0.024895703 | K7: K20D50M | L7: =G11 -> 34 | M7: =F11 -> 26 | N7: =E11 -> 63 | O7: =D11 -> 42 | P7: =C11 -> 157 | Q7: =B11 -> 509
K8: K64F | L8: =G3 -> 3.1 | M8: =F3 -> 2.86 | N8: =E3 -> 4.5 | O8: =D3 -> 3.6 | P8: =C3 -> 10.6 | Q8: =B3 -> 50.5
A9: K20D50M with MULT2-B, all algorithms CW Build
B10: 9-axis | C10: Accel/Gyro | D10: Accel/Mag | E10: Gyro Only | F10: 2D Mag | G10: Accel (Tilt) | K10: Memory sizes for CodeWarrior Builds
A11: Fusion K Systicks | B11: 509 | C11: 157 | D11: 42 | E11: 63 | F11: 26 | G11: 34 | H11: =SUM(B11:G11) -> 831 | L11: Text | M11: Data | N11: BSS | O11: Flash | P11: RAM
A12: Total K Systicks | B12: 1920 | C12: 1920 | D12: 1920 | E12: 1920 | F12: 1920 | G12: 1920 | H12: =AVERAGE(B12:G12) -> 1920 | I12: =H12*25*1000 -> 48000000 | K12: KL25Z | L12: 96028 | M12: 72 | N12: 14776 | O12: =L12+M12 -> 96100 | P12: =M12+N12 -> 14848
A13: % Fusion | B13: =B11/B12 -> 0.26510417 | C13: =C11/C12 -> 0.081770833 | D13: =D11/D12 -> 0.021875 | E13: =E11/E12 -> 0.0328125 | F13: =F11/F12 -> 0.013541667 | G13: =G11/G12 -> 0.017708333 | K13: KL26Z | L13: 96020 | M13: 72 | N13: 14780 | O13: =L13+M13 -> 96092 | P13: =M13+N13 -> 14852
A14: Total IDD (mA) | B14: 13.3 | C14: 13.3 | D14: 13.3 | E14: 13.2 | F14: 13.2 | G14: 13.2 | K14: KL46Z | L14: 95956 | M14: 72 | N14: 14780 | O14: =L14+M14 -> 96028 | P14: =M14+N14 -> 14852
A15: Fusion IDD (mA) | B15: =B13*B14 -> 3.5258854 | C15: =C13*C14 -> 1.0875521 | D15: =D13*D14 -> 0.2909375 | E15: =E13*E14 -> 0.433125 | F15: =F13*F14 -> 0.17875 | G15: =G13*G14 -> 0.23375 | K15: K20D50M | L15: 88116 | M15: 72 | N15: 14972 | O15: =L15+M15 -> 88188 | P15: =M15+N15 -> 15044
K16: K64F | L16: 79724 | M16: 84 | N16: 16484 | O16: =L16+M16 -> 79808 | P16: =M16+N16 -> 16568
A17: KL46Z with MULT2-B, all algorithms CW Build
B18: 9-axis | C18: Accel/Gyro | D18: Accel/Mag | E18: Gyro Only | F18: 2D Mag | G18: Accel (Tilt)
A19: Fusion K Systicks | B19: 740 | C19: 207 | D19: 72 | E19: 171 | F19: 45 | G19: 59 | H19: =SUM(B19:G19) -> 1294 | K19: Table 9: KL26Z Currents | O19: 9-Axis Currents
A20: Total K Systicks | B20: 1920 | C20: 1920 | D20: 1920 | E20: 1920 | F20: 1920 | G20: 1920 | H20: =AVERAGE(B20:G20) -> 1920 | I20: =H20*25*1000 -> 48000000 | K20: Function | L20: FusionIdd@25Hz rate | M20: Fusion Idd/Hz | P20: CW | Q20: KDW
A21: % Fusion | B21: =B19/B20 -> 0.38541667 | C21: =C19/C20 -> 0.1078125 | D21: =D19/D20 -> 0.0375 | E21: =E19/E20 -> 0.0890625 | F21: =F19/F20 -> 0.0234375 | G21: =G19/G20 -> 0.030729167 | K21: =G26 -> Accel (Tilt) | L21: =G31 -> 0.25085982 | M21: =L21/25 -> 0.010034393 | O21: K64F | P21: =B7 -> 0.40029203 | Q21: ='KDS - ALL'!B7 -> 0.5107375
A22: Total IDD (mA) | B22: 9.6 | C22: 9.7 | D22: 9.5 | E22: 9.6 | F22: 9.5 | G22: 9.6 | K22: =F26 -> 2D Mag | L22: =F31 -> 0.19463262 | M22: =L22/25 -> 0.0077853048 | O22: K22F | P22: N/A | Q22: ='KDS - ALL'!B15 -> 0.41493125
A23: Fusion IDD (mA) | B23: =B21*B22 -> 3.7 | C23: =C21*C22 -> 1.0457812 | D23: =D21*D22 -> 0.35625 | E23: =E21*E22 -> 0.855 | F23: =F21*F22 -> 0.22265625 | G23: =G21*G22 -> 0.295 | K23: =E26 -> Gyro Only | L23: =E31 -> 0.73921875 | M23: =L23/25 -> 0.02956875 | O23: K20D50M | P23: =B15 -> 3.5258854 | Q23: ='KDS - ALL'!B23 -> 4.1083333
K24: =D26 -> Accel/Mag | L24: =D31 -> 0.30708702 | M24: =L24/25 -> 0.012283481 | O24: KL46Z | P24: =B23 -> 3.7 | Q24: ='KDS - ALL'!B31 -> 4.15625
A25: KL26Z with MULT2-B, all algorithms CW Build | K25: =C26 -> Accel/Gyro | L25: =C31 -> 0.91922876 | M25: =L25/25 -> 0.036769151 | O25: KL26Z | P25: =B31 -> 3.2006253 | Q25: ='KDS - ALL'!B39 -> 3.7625
B26: 9-axis | C26: Accel/Gyro | D26: Accel/Mag | E26: Gyro Only | F26: 2D Mag | G26: Accel (Tilt) | K26: =B26 -> 9-axis | L26: =B31 -> 3.2006253 | M26: =L26/25 -> 0.12802501 | O26: KL25 | P26: =B39 -> 2.4666667 | Q26: ='KDS - ALL'!B47 -> 2.93125
A27: Fusion K Systicks | B27: 740 | C27: 210 | D27: 71 | E27: 171 | F27: 45 | G27: 58 | H27: =SUM(B27:G27) -> 1295 | K27: subtotal | L27: =SUM(L21:L26) -> 5.6116523 | M27: =SUM(M21:M26) -> 0.22446609
A28: Total K Systicks | B28: 1919 | C28: 1919 | D28: 1919 | E28: 1920 | F28: 1919 | G28: 1919 | H28: =AVERAGE(B28:G28) -> 1919.1667 | I28: =H28*25*1000 -> 47979167 | K28: estimated RTOS/other | L28: =8.4-L27 -> 2.7883477 | M28: =SUM(M22:M27) -> 0.43889779
A29: % Fusion | B29: =B27/B28 -> 0.38561751 | C29: =C27/C28 -> 0.109432 | D29: =D27/D28 -> 0.036998437 | E29: =E27/E28 -> 0.0890625 | F29: =F27/F28 -> 0.023449713 | G29: =G27/G28 -> 0.030224075
A30: Total IDD (mA) | B30: 8.3 | C30: 8.4 | D30: 8.3 | E30: 8.3 | F30: 8.3 | G30: 8.3
A31: Fusion IDD (mA) | B31: =B29*B30 -> 3.2006253 | C31: =C29*C30 -> 0.91922876 | D31: =D29*D30 -> 0.30708702 | E31: =E29*E30 -> 0.73921875 | F31: =F29*F30 -> 0.19463262 | G31: =G29*G30 -> 0.25085982
A33: KL25Z with MULT2-B, all algorithms CW Build
B34: 9-axis | C34: Accel/Gyro | D34: Accel/Mag | E34: Gyro Only | F34: 2D Mag | G34: Accel (Tilt)
A35: Fusion K Systicks | B35: 740 | C35: 208 | D35: 72 | E35: 172 | F35: 46 | G35: 58 | H35: =SUM(B35:G35) -> 1296
A36: Total K Systicks | B36: 1920 | C36: 1920 | D36: 1920 | E36: 1920 | F36: 1920 | G36: 1920 | H36: =AVERAGE(B36:G36) -> 1920 | I36: =H36*25*1000 -> 48000000
A37: % Fusion | B37: =B35/B36 -> 0.38541667 | C37: =C35/C36 -> 0.10833333 | D37: =D35/D36 -> 0.0375 | E37: =E35/E36 -> 0.089583333 | F37: =F35/F36 -> 0.023958333 | G37: =G35/G36 -> 0.030208333
A38: Total IDD (mA) | B38: 6.4 | C38: 6.4 | D38: 6.4 | E38: 6.4 | F38: 6.4 | G38: 6.4
A39: Fusion IDD (mA) | B39: =B37*B38 -> 2.4666667 | C39: =C37*C38 -> 0.69333333 | D39: =D37*D38 -> 0.24 | E39: =E37*E38 -> 0.57333333 | F39: =F37*F38 -> 0.15333333 | G39: =G37*G38 -> 0.19333333 | H39: =SUM(B39:G39) -> 4.32
A41: On this page, total systicks are measured. On KDS page I just used the theoretical

Sheet KDS - ALL
A1: K64F with MULT2-B, all algorithms KDS Build
B2: 9-axis | C2: Accel/Gyro | D2: Accel/Mag | E2: Gyro Only | F2: 2D Mag | G2: Accel (Tilt) | J2: Table 14 for KDS (Fusion K SysTicks)
A3: Fusion K Systicks | B3: 54.6 | C3: 11.4 | D3: 3.9 | E3: 4.9 | F3: 3.1 | G3: 3.3 | H3: =SUM(B3:G3) -> 81.2 | K3: =G2 -> Accel (Tilt) | L3: =F2 -> 2D Mag | M3: =E2 -> Gyro Only | N3: =D2 -> Accel/Mag | O3: =C2 -> Accel/Gyro | P3: =B2 -> 9-axis
A4: Total K Systicks | B4: =$H4/25 -> 4800 | C4: =$H4/25 -> 4800 | D4: =$H4/25 -> 4800 | E4: =$H4/25 -> 4800 | F4: =$H4/25 -> 4800 | G4: =$H4/25 -> 4800 | H4: 120000 | J4: KL25Z | K4: =G43 -> 59 | L4: =F43 -> 47 | M4: =E43 -> 174 | N4: =D43 -> 74 | O4: =C43 -> 211 | P4: =B43 -> 840
A5: % Fusion | B5: =B3/B4 -> 0.011375 | C5: =C3/C4 -> 0.002375 | D5: =D3/D4 -> 0.0008125 | E5: =E3/E4 -> 0.0010208333 | F5: =F3/F4 -> 0.00064583333 | G5: =G3/G4 -> 0.0006875 | J5: KL26Z | K5: =G35 -> 61 | L5: =F35 -> 48 | M5: =E35 -> 173 | N5: =D35 -> 75 | O5: =C35 -> 211 | P5: =B35 -> 860
A6: Total IDD (mA) | B6: 44.9 | C6: 45 | D6: 44.9 | E6: 44.9 | F6: 44.9 | G6: 44.9 | J6: KL46Z | K6: =G27 -> 60 | L6: =F27 -> 49 | M6: =E27 -> 174 | N6: =D27 -> 74 | O6: =C27 -> 210 | P6: =B27 -> 840
A7: Fusion IDD (mA) | B7: =B5*B6 -> 0.5107375 | C7: =C5*C6 -> 0.106875 | D7: =D5*D6 -> 0.03648125 | E7: =E5*E6 -> 0.045835417 | F7: =F5*F6 -> 0.028997917 | G7: =G5*G6 -> 0.03086875 | J7: K20D50M | K7: =G19 -> 35 | L7: =F19 -> 27 | M7: =E19 -> 66 | N7: =D19 -> 44 | O7: =C19 -> 160 | P7: =B19 -> 580
J8: K64F | K8: =G3 -> 3.3 | L8: =F3 -> 3.1 | M8: =E3 -> 4.9 | N8: =D3 -> 3.9 | O8: =C3 -> 11.4 | P8: =B3 -> 54.6
A9: K22F with MULT2-B, all algorithms KDS Build | J9: K22F | K9: =G11 -> 3.9 | L9: =F11 -> 3.7 | M9: =E11 -> 5.8 | N9: =D11 -> 4.4 | O9: =C11 -> 13.4 | P9: =B11 -> 59.1
B10: 9-axis | C10: Accel/Gyro | D10: Accel/Mag | E10: Gyro Only | F10: 2D Mag | G10: Accel (Tilt)
A11: Fusion K Systicks | B11: 59.1 | C11: 13.4 | D11: 4.4 | E11: 5.8 | F11: 3.7 | G11: 3.9 | J11: Memory sizes for KDS builds
A12: Total K Systicks | B12: 4800 | C12: 4800 | D12: 4800 | E12: 4800 | F12: 4800 | G12: 4800 | K12: Text | L12: Data | M12: BSS | N12: Flash | O12: RAM
A13: % Fusion | B13: =B11/B12 -> 0.0123125 | C13: =C11/C12 -> 0.0027916667 | D13: =D11/D12 -> 0.00091666667 | E13: =E11/E12 -> 0.0012083333 | F13: =F11/F12 -> 0.00077083333 | G13: =G11/G12 -> 0.0008125 | J13: KL25Z | K13: 77812 | L13: 172 | M13: 14816 | N13: =K13+L13 -> 77984 | O13: =L13+M13 -> 14988
A14: Total IDD (mA) | B14: 33.7 | C14: 33.7 | D14: 33.6 | E14: 33.6 | F14: 33.6 | G14: 33.6 | J14: KL26Z | K14: 77828 | L14: 172 | M14: 14816 | N14: =K14+L14 -> 78000 | O14: =L14+M14 -> 14988
A15: Fusion IDD (mA) | B15: =B13*B14 -> 0.41493125 | C15: =C13*C14 -> 0.094079167 | D15: =D13*D14 -> 0.0308 | E15: =E13*E14 -> 0.0406 | F15: =F13*F14 -> 0.0259 | G15: =G13*G14 -> 0.0273 | H15: =SUM(B15:G15) -> 0.63361042 | J15: KL46Z | K15: 77772 | L15: 172 | M15: 14816 | N15: =K15+L15 -> 77944 | O15: =L15+M15 -> 14988
J16: K20D50M | K16: 67356 | L16: 172 | M16: 15008 | N16: =K16+L16 -> 67528 | O16: =L16+M16 -> 15180
A17: K20D50M with MULT2-B, all algorithms KDS Build | J17: K64F | K17: 65024 | L17: 184 | M17: 16652 | N17: =K17+L17 -> 65208 | O17: =L17+M17 -> 16836
B18: 9-axis | C18: Accel/Gyro | D18: Accel/Mag | E18: Gyro Only | F18: 2D Mag | G18: Accel (Tilt) | J18: K22F | K18: 62268 | L18: 184 | M18: 16492 | N18: =K18+L18 -> 62452 | O18: =L18+M18 -> 16676
A19: Fusion K Systicks | B19: 580 | C19: 160 | D19: 44 | E19: 66 | F19: 27 | G19: 35 | H19: =SUM(B19:G19) -> 912
A20: Total K Systicks | B20: =$H20/25 -> 1920 | C20: =$H20/25 -> 1920 | D20: =$H20/25 -> 1920 | E20: =$H20/25 -> 1920 | F20: =$H20/25 -> 1920 | G20: =$H20/25 -> 1920 | H20: 48000
A21: % Fusion | B21: =B19/B20 -> 0.30208333 | C21: =C19/C20 -> 0.083333333 | D21: =D19/D20 -> 0.022916667 | E21: =E19/E20 -> 0.034375 | F21: =F19/F20 -> 0.0140625 | G21: =G19/G20 -> 0.018229167
A22: Total IDD (mA) | B22: 13.6 | C22: 13.4 | D22: 13.4 | E22: 13.3 | F22: 13.3 | G22: 13.3
A23: Fusion IDD (mA) | B23: =B21*B22 -> 4.1083333 | C23: =C21*C22 -> 1.1166667 | D23: =D21*D22 -> 0.30708333 | E23: =E21*E22 -> 0.4571875 | F23: =F21*F22 -> 0.18703125 | G23: =G21*G22 -> 0.24244792
A25: KL46Z with MULT2-B, all algorithms KDS Build
B26: 9-axis | C26: Accel/Gyro | D26: Accel/Mag | E26: Gyro Only | F26: 2D Mag | G26: Accel (Tilt)
A27: Fusion K Systicks | B27: 840 | C27: 210 | D27: 74 | E27: 174 | F27: 49 | G27: 60 | H27: =SUM(B27:G27) -> 1407
A28: Total K Systicks | B28: =$H28/25 -> 1920 | C28: =$H28/25 -> 1920 | D28: =$H28/25 -> 1920 | E28: =$H28/25 -> 1920 | F28: =$H28/25 -> 1920 | G28: =$H28/25 -> 1920 | H28: 48000
A29: % Fusion | B29: =B27/B28 -> 0.4375 | C29: =C27/C28 -> 0.109375 | D29: =D27/D28 -> 0.038541667 | E29: =E27/E28 -> 0.090625 | F29: =F27/F28 -> 0.025520833 | G29: =G27/G28 -> 0.03125
A30: Total IDD (mA) | B30: 9.5 | C30: 9.4 | D30: 9.3 | E30: 9.3 | F30: 9.3 | G30: 9.3
A31: Fusion IDD (mA) | B31: =B29*B30 -> 4.15625 | C31: =C29*C30 -> 1.028125 | D31: =D29*D30 -> 0.3584375 | E31: =E29*E30 -> 0.8428125 | F31: =F29*F30 -> 0.23734375 | G31: =G29*G30 -> 0.290625
A33: KL26Z with MULT2-B, all algorithms KDS Build
B34: 9-axis | C34: Accel/Gyro | D34: Accel/Mag | E34: Gyro Only | F34: 2D Mag | G34: Accel (Tilt)
A35: Fusion K Systicks | B35: 860 | C35: 211 | D35: 75 | E35: 173 | F35: 48 | G35: 61 | H35: =SUM(B35:G35) -> 1428
A36: Total K Systicks | B36: =$H36/25 -> 1920 | C36: =$H36/25 -> 1920 | D36: =$H36/25 -> 1920 | E36: =$H36/25 -> 1920 | F36: =$H36/25 -> 1920 | G36: =$H36/25 -> 1920 | H36: 48000
A37: % Fusion | B37: =B35/B36 -> 0.44791667 | C37: =C35/C36 -> 0.10989583 | D37: =D35/D36 -> 0.0390625 | E37: =E35/E36 -> 0.090104167 | F37: =F35/F36 -> 0.025 | G37: =G35/G36 -> 0.031770833
A38: Total IDD (mA) | B38: 8.4 | C38: 8.3 | D38: 8.3 | E38: 8.3 | F38: 8.3 | G38: 8.3
A39: Fusion IDD (mA) | B39: =B37*B38 -> 3.7625 | C39: =C37*C38 -> 0.91213542 | D39: =D37*D38 -> 0.32421875 | E39: =E37*E38 -> 0.74786458 | F39: =F37*F38 -> 0.2075 | G39: =G37*G38 -> 0.26369792
A41: KL25Z with MULT2-B, all algorithms KDS Build
B42: 9-axis | C42: Accel/Gyro | D42: Accel/Mag | E42: Gyro Only | F42: 2D Mag | G42: Accel (Tilt)
A43: Fusion K Systicks | B43: 840 | C43: 211 | D43: 74 | E43: 174 | F43: 47 | G43: 59 | H43: =SUM(B43:G43) -> 1405
...

Sheet KL25Z Single Build Sizes
B4: Memory sizes for KL25Z Single Algorithm CodeWarrior Builds
C5: Text | D5: Data | E5: BSS | F5: Flash | G5: RAM
B6: Accel (Tilt) | C6: 34280 | D6: 64 | E6: 12580 | F6: =C6+D6 -> 34344 | G6: =D6+E6 -> 12644
B7: 2D Mag | C7: 53904 | D7: 64 | E7: 12580 | F7: =C7+D7 -> 53968 | G7: =D7+E7 -> 12644
B8: Gyro Only | C8: 33944 | D8: 64 | E8: 12528 | F8: =C8+D8 -> 34008 | G8: =D8+E8 -> 12592
B9: Accel/Mag | C9: 55172 | D9: 64 | E9: 12588 | F9: =C9+D9 -> 55236 | G9: =D9+E9 -> 12652
B10: Accel/Gyro | C10: 54716 | D10: 72 | E10: 12892 | F10: =C10+D10 -> 54788 | G10: =D10+E10 -> 12964
B11: 9-axis | C11: 75552 | D11: 64 | E11: 13664 | F11: =C11+D11 -> 75616 | G11: =D11+E11 -> 13728
